Workbook

Sheet Summary
A1: QuantumTech HotSpot Investment Universe Database
A3: Key Entitiyes & Modalities
A5: Top Quantum Computing Companies | N5: Top Quantum Cyber Security Companies
A6: Type | B6: Count | N6: Type | O6: Count
A7: Public Companies | B7: 10 | N7: Public Companies | O7: 8
A8: Promising IPO | B8: 9 | N8: Promising IPO | O8: 8
A9: Top Pre-IPO | B9: 10 | N9: Top Pre-IPO | O9: 10
A10: Promising Pre-IPO | B10: 10 | N10: Promising Pre-IPO | O10: 9
A11: Total | B11: =SUM(B7:B10) -> 39 | N11: Total | O11: =SUM(O7:O10) -> 35
A18: Top Quantum Computing Companies | N18: Investors by HotSpot
A19: Type | B19: Count | N19: HotSpot | O19: Count
A20: Public Companies | B20: 7 | N20: Quantum Computing | O20: 193
A21: Promising Pre-IPO | B21: 9 | N21: Cyber Security HotSpot | O21: 196
A22: Pre IPO Companies | B22: 9 | N22: Communications HotSpot | O22: 175
A23: Post Ipo Companies | B23: 7 | N23: Total | O23: =SUM(O20:O22) -> 564
A24: Total | B24: =SUM(B20:B23) -> 32
A30: Companies UDMs by HotSpot | N30: Investors UDMs by HotSpot
A31: HotSpot | B31: Count | N31: HotSpot | O31: Count
A32: Quantum Computing | B32: 101 | N32: Quantum Computing | O32: 570
A33: Cyber Security HotSpot | B33: 93 | N33: Cyber Security HotSpot | O33: 522
A34: Communications HotSpot | B34: 87 | N34: Communications HotSpot | O34: 420
A35: Total | B35: =SUM(B32:B34) -> 281 | N35: Total | O35: =SUM(O32:O34) -> 1512
A41: QuantumTech HotSpot Investment Universe Database
A42: Key Entitiyes & Modalities
A44: Quantum Bio & Medicine Companies | N44: Quantum Materials & NanoTech Companies
A45: Type | B45: Count | N45: Type | O45: Count
A46: Promising Private Companies | B46: 6 | N46: Promising Private Companies | O46: 6
A47: Pre IPO Companies | B47: 4 | N47: Pre IPO Companies | O47: 4
A48: Post IPO Companies | B48: 5 | N48: Post IPO Companies | O48: 4
A49: Public Companies | B49: 6 | N49: Public Companies | O49: 6
A50: Total | B50: =SUM(B46:B49) -> 21 | N50: Total | O50: =SUM(O46:O49) -> 20
A57: Quantum AI & ML Companies | N57: Investors
A58: Type | B58: Count | N58: HotSpot | O58: Count
A59: Promising Private Companies | B59: 6 | N59: Quantum Bio & Medicine | O59: 39
A60: Pre IPO Companies | B60: 4 | N60: Quantum Materials & NanoTech | O60: 51
A61: Post IPO Companies | B61: 5 | N61: Quantum AI & ML | O61: 50
A62: Public Companies | B62: 4 | N62: Total | O62: =SUM(O59:O61) -> 140
A63: Total | B63: =SUM(B59:B62) -> 19
A69: Companies UDMs | N69: Investors UDMs
A70: HotSpot | B70: Count | N70: HotSpot | O70: Count
...

Sheet Quantum Bio & Medicine 
A1: segment | B1: name | C1: Logo | D1: description | E1: short description | F1: website | G1: founded on | H1: num_employees_enum | I1: twitter | J1: facebook | K1: linkedin | L1: investors | M1: stock symbol | N1: went public on | O1: categories | P1: category groups | Q1: locations | R1: city | S1: region | T1: country | U1: founders | V1: contact email
A2: Promising Private Companies | B2: Algorithmiq | C2: Algorithmiq.png | D2: Algorithmiq develops algorithms to solve currently inaccessible problems in life sciences. The company utilizes its expertise in quantum information, complex systems, and computational physics to develop algorithms to develop new and effective drugs, solve problems in life sciences, and discover new materials. | E2: Algorithmiq develops algorithms to solve currently inaccessible problems in life sciences. | F2: https://algorithmiq.fi | G2: 2020 | K2: https://www.linkedin.com/company/algorithmiq | L2: European Investment Bank,Tiger Global Management,K5 Global,Inventure,Tesi | O2: Biotechnology,Life Science,Market Research,Quantum Computing | Q2: Turku,Western Finland,Finland,Europe | R2: Turku | S2: Western Finland | T2: Finland | U2: Boris Sokolov,Guillermo GarciaPerez,Matteo Rossi,Sabrina Maniscalco | V2: info@algorithmiq.fi
B3: Polaris Quantum Biotech | C3: Polaris Quantum Biotech.png | D3: Polaris Quantum Biotech is revolutionizing drug design by combining quantum computing with artificial intelligence and precision medicine. By unifying these technologies, the company is able to search massive chemical libraries, identifying potential drugs that target proteins for specific disease modulations. The company was founded in 2020 and is headquartered in Durham, North Carolina. | E3: Polaris Quantum Biotech revolutionizes drug design by joining quantum computing with AI and precision medicine. | F3: https://www.polarisqb.com/ | G3: 2020 | I3: https://x.com/polarisqb | K3: https://www.linkedin.com/company/polarisqb/ | L3: OurCrowd,Infinity Medical | O3: Artificial Intelligence (AI),Biotechnology,Health Care,Precision Medicine,Quantum Computing | Q3: Durham,North Carolina,United States,North America | R3: Durham | S3: North Carolina | T3: United States | U3: Bill Shipman,Shahar Keinan | V3: info@polarisqb.com
B4: Menten AI | C4: Menten AI.png | D4: Menten AI designs new protein drugs and enzymes using quantum computers and machine learning. Proteins are large molecules that can twist into many shapes. Discovering the right shape for a protein to be a drug or a biocatalyst among almost endless possibilities is a major challenge. Menten AI solves this problem by using machine learning and quantum computing to find better starting points for discovery and further development. Quantum computing makes it possible to represent multiple states of the protein simultaneously and efficiently find the best designs. The team created the world’s first peptide designed on a quantum computer and is now working on peptide therapeutics for oncology and neurodegeneration, as well as on enzymes for industrial applications. | E4: Menten AI develops peptide and protein therapeutics using machine learning and quantum computing. | F4: http://menten.ai/ | G4: 2018 | I4: https://x.com/menten_ai | K4: https://www.linkedin.com/company/mentenai/ | L4: Alumni Ventures,Khosla Ventures,Y Combinator,Uncork Capital,Creative Destruction Lab (CDL) | O4: Artificial Intelligence (AI),Biotechnology,Chemical,Health Care,Life Science,Machine Learning,Pharmaceutical,Quantum Computing,Therapeutics | Q4: Palo Alto,California,United States,North America | R4: Palo Alto | S4: California | T4: United States | U4: Hans Melo,Tamas Gorbe,Vikram K. Mulligan | V4: info@menten.ai
B5: Qubit Pharmaceuticals | C5: Qubit Pharmaceuticals.png | D5: Qubit Pharmaceuticals is a brandnew international company based in Paris that was founded by CNAM, CNRS, the University of Texas at Austin, the Sorbonne University, and Washington University. Qubit Pharmaceuticals is built on more than 20 years of R and D that has been recognized with the most prestigious awards. It was founded by Pr Jay Ponder, Pr Pengyu Ren, Pr J.P. Piquemal, Dr Louis Lagardere, and Pr Matthieu Montes. | E5: Qubit Pharmaceuticals is an EIT Health Headstart laureate and is incubated at Paris Biotech Santé. | F5: https://www.qubitpharmaceuticals.com | G5: 2020 | H5: 51-100 | K5: https://www.linkedin.com/company/qubitpharmaceuticals | L5: Quantonation,XAnge,Omnes Capital,European Innovation Council,Octave Klaba | O5: Biotechnology | Q5: Paris,IledeFrance,France,Europe | R5: Paris | S5: IledeFrance | T5: France | U5: Jay Ponder,Jean Philip Piquemal,Matthieu Montes
B6: Quomics | C6: Quomics.png | D6: Q‑omics is an AI‑powered multi‑omics intelligence platform that helps life‑science and biotech organizations analyze and integrate complex genomic, transcriptomic, proteomic, and metabolomic data for drug discovery, precision medicine, and translational research. | E6: AI‑driven multi‑omics analytics platform for life‑science R&D. | F6: https://qomics.ai | G6: 2024 | H6: 1–10 | O6: multi‑omics, AI, genomics, bioinformatics, drug discovery | P6: healthtech, biotech, AI / data‑analytics | Q6: Seoul (registered in Republic of Korea) | R6: Seoul | T6: Republic of Korea | U6: SukJoon Yoon | V6: qomics.io@gmail.com
B7: QuantumDance | C7: QuantumDance.png | D7: QuantumDance Technologies applies quantum‑inspired and quantum‑AI algorithms to large‑scale biological data, including medical imaging, multi‑omics, and clinical datasets, to accelerate drug discovery, improve diagnostic accuracy, and identify novel biomarkers for healthcare providers and pharma companies. | E7: Quantum‑AI engine for healthcare and multi‑omics. | F7: https://quantumdance.io | H7: 1–10 | O7: quantum‑AI, healthcare AI, medical imaging, multi‑omics, drug discovery, biomarker discovery | P7: healthtech, AI, quantum computing for medicine | Q7: (remote / distributed) | T7: United States
A8: Pre IPO Companies | B8: Quantinuum | C8: Quantinuum.png | D8: Quantinuum is a quantum company dedicated to the advancement of quantum computers and the development of software solutions. Quantinuum's technology spearheads advancements in materials discovery, cybersecurity, and nextgeneration quantum AI. The company has nearly 500 professionals, including over 370 scientists and engineers, Quantinuum takes the helm in driving the quantum computing revolution globally. | E8: Quantinuum is a IT firm that accelerates quantum computing and the development of applications across chemistry, cybersecurity, and finance. | F8: https://www.quantinuum.com | G8: 2021 | H8: 501-1000 | I8: https://x.com/QuantinuumQC | J8: https://www.facebook.com/QuantinuumQC | K8: https://www.linkedin.com/company/quantinuumqc | L8: QED Investors,NVentures,Amgen,JP Morgan Chase,Korea Investment Partners | O8: Cyber Security,Quantum Computing,Software Engineering | Q8: Broomfield,Colorado,United States,North America | R8: Broomfield | S8: Colorado | T8: United States | U8: Ilyas Khan | V8: info@quantinuum.com
B9: SandboxAQ | C9: SandboxAQ.png | D9: SandboxAQ develops AI and quantum technology products aimed at solving complex challenges. The company integrates knowledge from various fields to create Large Quantitative Models and AI sensing applications. Its focus is on providing practical solutions in areas that require advanced computational techniques. The industries served include financial services, healthcare, and telecommunications. | E9: SandboxAQ develops AI and quantum technology solutions that enhance biopharma, cybersecurity, and materials science. | F9: https://www.sandboxaq.com | G9: 2016 | H9: 101-250 | I9: https://x.com/sandboxaq | K9: https://www.linkedin.com/company/sandboxaq | L9: NVIDIA,Paladin Capital Group,BNP Paribas,S32,US Innovative Technology Fund | O9: Artificial Intelligence (AI),Cyber Security,Information Technology,Quantum Computing,SaaS | Q9: Palo Alto,California,United States,North America | R9: Palo Alto | S9: California | T9: United States | U9: Jack Hidary | V9: info@sandboxaq.com
B10: Pasqal | C10: Pasqal.png | D10: PASQAL is developing a fullstack quantum computer that will be used to simulate complex phenomena for scientific discovery and to address general problems such as optimization, drug discovery, and machine learning. The company's quantum processing units are made up of hundreds of atomic qubits in 2D and 3D arrays, and their programming environment, to address our customers' needs in quantum computing and simulation. | E10: Pasqal develops neutral atombased quantum processors, simulators, and computers. | F10: https://www.pasqal.com | G10: 2019 | H10: 251-500 | I10: https://x.com/pasqal_quantum | J10: https://www.facebook.com/Pasqal.quantum.computing | K10: https://www.linkedin.com/company/pasqal | L10: Bpifrance,Temasek Holdings,Daphni,Quantonation,European Innovation Council | O10: Computer,Information Technology,Quantum Computing,Simulation | Q10: Palaiseau,IledeFrance,France,Europe | R10: Palaiseau | S10: IledeFrance | T10: France | U10: Alain Aspect,Antoine Browaeys,Christophe Jurczak,GeorgesOlivier Reymond,Thierry Lahaye | V10: nicolas.proust@pasqal.com
B11: QuEra | C11: QuEra.png | D11: QuEra is a software company specializing in cloud based SaaS data collection and automation solutions for healthcare, specifically mental health. With QuEra software data collection and analysis processes are streamlined and overhead eliminated. They provide solutions for clinical psychologists and other mental professionals to digitize self assessment questionnaires and other psychometric instruments. The entire process from data collection, scoring, processing and storage becomes digital eliminating overhead, errors and improving outcomes and reliability | E11: SaaS company for healthcare data collection and automated systems | F11: https://quera.io | G11: 2007 | I11: https://x.com/Quera34731567 | J11: https://www.facebook.com/quera.io | K11: https://www.linkedin.com/company/queraio | O11: Data Collection and Labeling,Electronic Health Record (EHR),Health Care,Information Technology,Personal Health,SaaS,Software | Q11: Reykjavík,Gullbringusysla,Iceland,Europe | R11: Reykjavík | S11: Gullbringusysla | T11: Iceland | V11: hello@quera.io
A12: Post IPO Companies | B12: D-Wave Quantum | C12: D-Wave Quantum.png | D12: DWave provides development and delivery of quantum computing systems, software and services, and is the world’s first commercial supplier of quantum computers—and the only company building both annealing quantum computers and gatemodel quantum computers. Our mission is to unlock the power of quantum computing today to benefit business and society. | E12: DWave Systems designs and manufactures quantum computing and superconducting electronics. | F12: https://www.dwavequantum.com | G12: 1999 | H12: 101-250 | I12: https://x.com/dwavesys | J12: https://www.facebook.com/dwavesys | K12: http://www.linkedin.com/company/dwavesystemsinc. | L12: Business Development Bank of Canada,Goldman Sachs,Fidelity,Government of Canada,SCALE AI | M12: QBTS | N12: 20220808 | O12: Electronics,Manufacturing,Quantum Computing,Semiconductor | Q12: Palo Alto,California,United States,North America | R12: Palo Alto | S12: California | T12: United States | U12: Eric Ladizinsky,Geordie Rose | V12: info@dwavesys.com
B13: Rigetti Computing | C13: Rigetti Computing.png | D13: Rigetti Computing is a fullstack quantum computing company. It designs and manufactures quantumintegrated circuits. It packages and deploys those chips in a lowtemperature environment, and they build control systems to perform quantum logic operations on them. The company develops software to integrate its systems directly into existing cloud infrastructure. It has also developed new algorithms for quantum computing, with a focus on nearterm applications in computational chemistry and machine learning. Our product, Forest, is the world’s first fullstack programming and execution environment for quantum/classical computing. | E13: Rigetti Computing is a quantum computing company that builds and deploys fullstack quantum systems with superconducting qubits. | F13: http://www.rigetti.com | G13: 2013 | H13: 101-250 | I13: https://x.com/rigetti | J13: https://www.facebook.com/rigetticomputing | K13: https://www.linkedin.com/company/rigetticomputing | L13: Andreessen Horowitz,Franklin Templeton,Alumni Ventures,Bessemer Venture Partners,Felicis | M13: RGTI | N13: 20220302 | O13: AI Infrastructure,Artificial Intelligence (AI),Big Data,Hardware,Quantum Computing,Semiconductor,Software | Q13: Berkeley,California,United States,North America | R13: Berkeley | S13: California | T13: United States | U13: Chad Rigetti,Spencer Rascoff | V13: info@rigetti.com
B14: IonQ | C14: IonQ.png | D14: IONQ develops generalpurpose quantum information processor using a trapped ion approach. The method enables qubit replication optical networkability, and optimized algorithms to support scalable quantum computing. | E14: IONQ offers enterprisegrade quantum systems designed for businesses seeking to harness the power of quantum computing in their operations. | F14: https://ionq.com | G14: 2015 | H14: 251-500 | I14: https://x.com/IonQ_Inc | J14: https://www.facebook.com/profile.php?id=100068180767172 | K14: https://www.linkedin.com/company/ionq.co | L14: Bosch Ventures,Lockheed Martin Ventures,Fidelity,New Enterprise Associates,OUP (Osage University Partners) | M14: DMYT | N14: 20200220 | O14: Computer,Electronics,Finance,Information Services,Information Technology,Mobile Apps,Quantum Computing,Software | Q14: College Park,Maryland,United States,North America | R14: College Park | S14: Maryland | T14: United States | U14: Christopher Monroe,Jungsang Kim,Niccolo de Masi | V14: info@ionq.com
B15: XtalPi | C15: XtalPi.png | D15: XtalPi is a pharmaceutical technology company that is reinventing the industry’s approach to drug research and development with its Intelligent Digital Drug Discovery and Development (ID4) platform. Through its tightly interwoven quantum mechanics, artificial intelligence, and highperformance cloud computing algorithms, the ID4 platform enables pharmaceutical companies to increase their efficiency, accuracy, and success rate at critical stages of drug R&D. By accelerating the pace of drug discovery and development, XtalPi aims to contribute to a healthier society worldwide. Founded in 2014 by a group of quantum physicists at MIT, XtalPi has since grown into an elite team of researchers with multidisciplinary expertise in physics, chemistry, pharmaceutical R&D, and algorithm design. XtalPi has received much recognition for its cuttingedge technologies, its innovative solutions, and the breadth of potential applications of its offerings across the pharmaceutical value chain, which has allowed it to gain industry approval and establish strategic partnerships with several top international pharmaceutical companies. | E15: XtalPi is a pharmaceutical technology company that is reinventing drug discovery by enabling dry lab predictions with wet lab validation. | F15: http://www.xtalpi.com/ | G15: 2015 | H15: 501-1000 | I15: https://x.com/xtalpi | K15: https://www.linkedin.com/company/xtalpi/ | L15: HSG,Tencent,OrbiMed,Shunwei Capital,Alphabet | M15: 2228 | N15: 20240613 | O15: Artificial Intelligence (AI),Biotechnology,Pharmaceutical | Q15: Shenzhen,Guangdong,China,Asia | R15: Shenzhen | S15: Guangdong | T15: China | U15: Jian Ma,Lipeng Lai,Shuhao Wen | V15: contact@xtalpi.com
B16: Zapata AI | C16: Zapata AI.png | E16: Zapata AI builds operational support platforms for enterprise solutions using augmented intelligence and machine learning. | F16: https://zapataai.com | G16: 2018 | O16: Artificial Intelligence (AI),Augmented Reality,Machine Learning,Software | Q16: Augusta,Georgia,United States,North America | R16: Augusta | S16: Georgia | T16: United States | V16: mediainquiries@zapataai.com
A17: Public Companies | B17: NVIDIA | C17: NVIDIA.png | D17: NVIDIA is a computing platform company innovating at the intersection of graphics, HPC and AI. The company specialises in the manufacture of graphics processor technologies for workstations, desktop computers, and mobile devices. The company is a major supplier of integrated circuits used for personal computer motherboard chipsets, graphics processing units (GPUs), and game consoles. | E17: NVIDIA is a computing platform company operating at the intersection of graphics, HPC, and AI. | F17: https://www.nvidia.com | G17: 1993 | H17: 10001+ | I17: https://x.com/nvidia | J17: https://www.facebook.com/NVIDIA.AP | K17: https://www.linkedin.com/company/nvidia | L17: Sequoia Capital,SoftBank Vision Fund,ARK Investment Management,DARPA,TriplePoint Capital | M17: NVDA | N17: 19990122 | O17: AI Infrastructure,Artificial Intelligence (AI),Consumer Electronics,Foundational AI,GPU,Hardware,Software,Virtual Reality | Q17: Santa Clara,California,United States,North America | R17: Santa Clara | S17: California | T17: United States | U17: Chris Malachowsky,Curtis Priem,Jensen Huang | V17: info@nvidia.com
B18: IBM | C18: IBM.png | D18: IBM is a technology and innovation company that offers a wide range of technology and consulting services; a broad portfolio of middleware for collaboration, predictive analytics, software development, and systems management. It offers services across AI, machine learning, cybersecurity, analytics, DevOps, and more, helping businesses innovate and automate processes. | E18: IBM is an IT technology and consulting firm providing computer hardware, software, infrastructure, and hosting services. | F18: http://www.ibm.com | G18: 1911 | H18: 10001+ | I18: https://x.com/IBM | J18: https://www.facebook.com/IBM | K18: https://www.linkedin.com/company/ibm | M18: IBM | N18: 19780113 | O18: Business Development,Business Information Systems,CRM,Data Management,Foundational AI,Software | Q18: Armonk,New York,United States,North America | R18: Armonk | S18: New York | T18: United States | U18: Gerard Aldus,Thomas J. Watson | V18: ews@us.ibm.com
B19: AstraZeneca | C19: AstraZeneca.png | D19: AstraZeneca is a biopharmaceutical company specializing in the discovery, development, manufacturing, and marketing of prescription medicines that make a meaningful difference in healthcare. It discovers new medicines that are designed to improve the health and quality of life of patients, offering added benefits such as reduced side effects or better ways of taking the treatment. It focuses on getting the best from every medicine it makes by exploring all the ways it can be used or improved. | E19: AstraZeneca is a pharmaceutical company that discovers, develops, manufactures, and markets prescription medicines. | F19: https://www.astrazeneca.com | G19: 1913 | H19: 10001+ | I19: https://x.com/astrazeneca | J19: https://www.facebook.com/astrazenecacareers | K19: http://www.linkedin.com/company/astrazeneca | M19: AZN | N19: 19930601 | O19: Biopharma,Biotechnology,Health Care,Medical,Pharmaceutical,Precision Medicine | Q19: Cambridge,Cambridgeshire,United Kingdom,Europe | R19: Cambridge | S19: Cambridgeshire | T19: United Kingdom
B20: Bayer | C20: Bayer.png | D20: Bayer is an enterprise with core competencies in the life science fields of healthcare and nutrition. They design their products and services to help people and the planet thrive by supporting efforts to address unprecedented challenges. Their businesses include pharmaceuticals, consumer health, and crop science. They focus on developing and commercializing products and solutions based on scientific knowledge. | E20: Bayer is a life science company that specializes in the areas of health care and agriculture. | F20: https://www.bayer.com | G20: 1863 | H20: 10001+ | I20: https://x.com/bayer | J20: http://www.facebook.com/Bayer | K20: https://www.linkedin.com/company/bayer | L20: Bill & Melinda Gates Foundation,Temasek Holdings,Bank of America | M20: BAYN | N20: 20091002 | O20: Biotechnology,Chemical,Health Care,Life Science,Pharmaceutical | Q20: Leverkusen,NordrheinWestfalen,Germany,Europe | R20: Leverkusen | S20: NordrheinWestfalen | T20: Germany | U20: Friedrich Bayer,Johann Friedrich Weskott | V20: info@bayer.com
B21: Alphabet (Google) | C21: Alphabet (Google).png | D21: Alphabet is a holding company that provides projects with resources, freedom, and focus to make their ideas happen. Alphabet is the holding company for Google and several Google entities, including Google X, Google Ventures, Google Capital, Calico, and its Life Sciences efforts. The company's CEO, Larry Page announced the operational restructuring effort for Alphabet Inc. to replace Google Inc. as the official publiclytraded entity. He announced that all shares of Google would automatically convert into the same number of shares of Alphabet, with all of the same rights. The two classes of shares will continue to trade on Nasdaq as GOOGL and GOOG. | E21: Alphabet is a holding company that provides projects with resources, freedom, and focus to make their ideas happen. | F21: https://abc.xyz | G21: 2015 | H21: 10001+ | I21: https://x.com/alphabetlnc | J21: https://www.facebook.com/alphabetxyz | K21: https://www.linkedin.com/company/alphabetinc | M21: GOOGL | N21: 20040819 | O21: Artificial Intelligence (AI),Information Technology,Search Engine,Software,Video Streaming | Q21: Mountain View,California,United States,North America | R21: Mountain View | S21: California | T21: United States | U21: Larry Page,Sergey Brin
B22: Merck KGaA | C22: Merck KGaA.png | D22: Merck (d.b.a. EMD Millipore in the U.S. and Canada) is a German chemical and pharmaceutical company. Merck, also known as “German Merck” and “Merck Darmstadt”, was founded in Darmstadt, Germany, in 1668, making it the world's oldest operating chemical and pharmaceutical company. The company was privately owned until going public in 1995. However, the Merck family still controls a majority (≈70%) of the company's shares. Following World War I, Merck lost possession of its foreign sites, including the Merck & Co. subsidiary in the United States. Merck & Co., which operates as Merck Sharp and Dohme (MSD) outside the U.S. and Canada, is now an independent company. Merck KGaA operates mainly in Europe, Africa, Asia, Oceania and Latin America. Since Merck & Co. holds the rights to the Merck name in the U.S. and Canada, the company operated under the umbrella brand EMD Chemicals in North America, and since 2010 as EMD Millipore (after the acquisition of Millipore Corporation), formed from the initials of Emanuel Merck, Darmstadt. Founded in 1668 in Darmstadt, Merck KGaA of Darmstadt, Germany, is the world's oldest pharmaceutical and chemical company. The success of the export business to the United States led in 1887 to the establishment of an office in New York, which gave rise to their subsidiary [Merck & Co.](http://www.crunchbase.com/organization/merckcoinc) four years later. Owing to World War I, Merck & Co. was expropriated in 1917. The two companies have been separate every since. Merck KGaA Subsidiaries: [Merck Consumer Healthcare](http://www.crunchbase.com/organization/merckconsumerhealthcare) [Merck Performance Materials](http://www.crunchbase.com/organization/merckperformancematerials) | E22: Merck is a pharmaceutical and chemical enterprise that develops prescription drugs and overthecounter products. | F22: https://www.merckgroup.com | G22: 1668 | H22: 10001+ | I22: https://x.com/merckgroup | J22: https://www.facebook.com/MerckDeutschland | K22: https://www.linkedin.com/company/merckgroup | L22: Scottish Enterprise | M22: MRK | N22: 20020111 | O22: Biotechnology,Health Care,Life Science,Manufacturing,Pharmaceutical | Q22: Darmstadt,Hessen,Germany,Europe | R22: Darmstadt | S22: Hessen | T22: Germany | U22: Friedrich Merck | V22: service@merckgroup.com

Sheet Quantum Bio & Medicine UDMs
A1: Name | B1: Photo | C1: LinkedIn | D1: Followers | E1: Email | F1: Title | G1: Company | H1: Company Industry | I1: Company Website | J1: Company Linkedin | K1: Company Founded In | L1: Company Size | M1: Current Job Duration | N1: Country | O1: Location | P1: Languages | Q1: Publications | R1: Honors And Awards | S1: Patents | T1: Volunteer and Awards | U1: License and Certifications | V1: Work Experience | W1: Education | X1: LinkedIn Summary | Y1: Headline | Z1: Photo
A2: Stephan Kudlacek | B2: Stephan Kudlacek.png | C2: https://www.linkedin.com/in/stephankudlacek | D2: 527 | E2: stephan.kudlacek@menten.ai | F2: Associate Director Protein Design | G2: Menten AI | H2: Biotechnology Research | I2: http://menten.ai | J2: https://www.linkedin.com/company/menten-ai/ | L2: 2-10 | M2: 3 yrs 8 mos | N2: United States | O2: Katy, Texas | Q2: Title: Physiological temperatures reduce dimerization of dengue and Zika virus recombinant envelope proteins Source: Journal of Biological Chemistry Summary: Abstract The spread of dengue (DENV) and Zika virus (ZIKV) is a major public health concern. The primary target of antibodies (Abs) that neutralize DENV and ZIKV is the envelope (E) glycoprotein, and there is interest in using soluble recombinant E (sRecE) proteins as subunit vaccines. However, the most potent neutralizing antibodies against DENV and ZIKV recognize epitopes on the virion surface that span two or more E proteins. Therefore, to create effective DENV and ZIKV vaccines, presentation of these quaternary epitopes may be necessary. The sRecE proteins from DENV and ZIKV crystallize as native-like dimers, but studies in solution suggest that these dimers are marginally stable. To better understand the challenges associated with creating stable sRecE dimers, we characterized the thermostability of sRecE proteins from ZIKV and three DENV serotypes, DENV2–4. All four proteins irreversibly unfolded at moderate temperatures (46°C–53°C). At 23°C and low micromolar concentrations, DENV2 and ZIKV were primarily dimeric, and DENV3–4 were primarily monomeric, whereas at 37°C, all four proteins were predominantly monomeric. We further show that the dissociation constant for DENV2 dimerization is very temperature sensitive, ranging from <1 μM at 25°C to 50 μM at 41°C, due to a large exothermic enthalpy of binding of –79 kcal/mol. We also found that quaternary epitope Ab binding to DENV2–4 and ZIKV sRecE is reduced at 37°C. Our observation of reduced sRecE dimerization at physiological temperature highlights the need for stabilizing the dimer as part of its development as a subunit vaccine. URL: https://www.ncbi.nlm.nih.gov/m/pubmed/29678884/?i=1&from=physiological%20temperatures%20reduce%20dimerization Title: Virus-Enabled Biosensor for Human Serum Albumin Source: ACS Analytical Chemistry Summary: Abstract: The label-free detection of human serum albumin (HSA) in aqueous buffer is demonstrated using a simple, monolithic, two-electrode electrochemical biosensor. In this device, both millimeter-scale electrodes are coated with a thin layer of a composite containing M13 virus particles and the electronically conductive polymer poly(3,4-ethylenedioxy thiophene) or PEDOT. These virus particles, engineered to selectively bind HSA, serve as receptors in this biosensor. The resistance component of the electrical impedance, Zre, measured between these two electrodes provides electrical transduction of HSA binding to the virus-PEDOT film. The analysis of sample volumes as small as 50 μL is made possible using a microfluidic cell. Upon exposure to HSA, virus-PEDOT films show a prompt increase in Zre within 5 s and a stable Zre signal within 15 min. HSA concentrations in the range from 100 nM to 5 μM are detectable. Sensor-to-sensor reproducibility of the HSA measurement is characterized by a coefficient-of-variance (COV) ranging from 2% to 8% across this entire concentration range. In addition, virus-PEDOT sensors successfully detected HSA in synthetic urine solutions. URL: http://pubs.acs.org/doi/abs/10.1021/acs.analchem.6b04840 Title: Shear-Stress-Mediated Refolding of Proteins from Aggregates and Inclusion Bodies Source: ChemBioChem Summary: Recombinant protein overexpression of large proteins in bacteria often results in insoluble and misfolded proteins directed to inclusion bodies. We report the application of shear stress in micrometer-wide, thin fluid films to refold boiled hen egg white lysozyme, recombinant hen egg white lysozyme, and recombinant caveolin-1. Furthermore, the approach allowed refolding of a much larger protein, cAMP-dependent protein kinase A (PKA). The reported methods require only minutes, which is more than 100 times faster than conventional overnight dialysis. This rapid refolding technique could significantly shorten times, lower costs, and reduce waste streams associated with protein expression for a wide range of industrial and research applications. URL: http://onlinelibrary.wiley.com/doi/10.1002/cbic.201402427/abstract Title: Focused dengue vaccine development: outwitting nature's design Source: Pathogens and Disease, Volume 77, Issue 1, February 2019 Summary: The four DENV serotypes are mosquito-borne pathogens that belong to the Flavivirus genus. These viruses present a major global health burden, being endemic in over 120 countries, causing ∼390 million reported infections yearly, with clinical symptoms ranging from mild fever to severe and potentially fatal hemorrhagic syndromes. Development of a safe and efficacious DENV vaccine is challenging because of the need to induce immunity against all four serotypes simultaneously, as immunity against one serotype can potentially enhance disease caused by a heterotypic secondary infection. So far, live-virus particle-based vaccine approaches struggle with inducing protective tetravalent immunity, while recombinant subunit approaches that use the envelope protein (E) as the major antigen, are gaining promise in preclinical studies. However, E-based subunits require further development and characterization to be used as effective vaccine antigens against DENV. In this review, we will address the shortcomings of recombinant E-based antigens and will discuss potential solutions to enhance E-based subunit antigen immunogenicity and vaccine efficacy. URL: https://academic.oup.com/femspd/article/77/1/ftz003/5307883 | S2: Title: Amino acid mutations for stabilizing the E protein dimer from Dengue virus. Issuer: US Provisional Patent UNC File No. 20-0009 Issued On: Aug , 2019 Description: None Title: Method for improving protein functionality using vortexing fluid shear forces Issuer: US Issued On: None Description: None | V2: Title: Associate Director Protein Design Company: None Start At: None Ends At: None Location: None Description: None Title: Senior Scientist, Protein Design Company: None Start At: None Ends At: None Location: None Description: None Title: PhD Candidate - Graduate Research Assistant Company: None Start At: None Ends At: None Location: None Description: None Title: Biomedical Research Assistant Company: None Start At: None Ends At: None Location: None Description: None | W2: School: The University of North Carolina at Chapel Hill Degree: Doctor of Philosophy - PhD, Biochemistry and Biophysics Activities: None School: UC Irvine Degree: Bachelor of Science, Chemistry with Biochemistry Concentration Activities: None | X2: • Driven and effective leader with +11 years research experience in protein engineering and biochemistry • Expert in both experimental and computational protein, antibody & cyclic peptide engineering and design • Head of Protein Design department & hiring manager managing a group of up to 10 scientists & contractors. • Led and contributed to cross-functional work with departments and partners in fields outside of expertise. • Lead for 6 internal drug discovery programs, including academic collaborations & large biotech commercial partnerships resulting in compounds with nM potency & in vivo efficacy. • Program lead of the company's computational cyclic peptide generative design platform. • Worked with CROs on protein production, purification, protein biophysical assay development. • Experienced in budget & resource management including cloud computing (AWS, GCP & Azure). • Representative research experience: vaccine antigen design, antibody engineering, computational macromolecular design, cyclic peptide therapeutics • Supervised scientists, contractors, PhD students, and undergraduates from different fields of expertise. • Google scholar list of publications and patents: https://scholar.google.com/citations?hl=en&user=zSQ1NEQAAAAJ&view_op=list_works&sortby=pubdate Skills Summary: - Protein & Peptide Libraries – Mammalian, yeast and phage display for high throughput screening - Biochemistry: Protein expression – Antibodies & proteins in bacteria, yeast, & mammalian cells; Affinity and SEC protein purification; Cloning – Restriction and recombination-based and plasmid construction - Biophysics: Thermodynamics & Kinetic binding measurements, ELISA, Protein Analysis & Structure Determination; Software – Pymol, Phenix, Coot, CCP4 - Bioinformatics: Protein & Peptide modeling; Software – Rosetta, Amber, OpenMM, Pymol, VMD; Programming – Bash, Python; - Immunology: Antigen preparation, serum antibody analysis, epitope mapping - Communication: Business development partner discussions & presentations, investor discussions & presentations, performance reviews, hiring interviews, government and private grant proposals, research conference presentations. | Y2: Associate Director - Protein Design at Menten AI | Z2: Stephan_Kudlacek.png
A3: Stefano Mangini | B3: Stefano Mangini.png | C3: https://www.linkedin.com/in/stfnmangini | D3: 1876 | E3: stefano.mangini@algorithmiq.fi | F3: Researcher | G3: Algorithmiq | H3: Research | I3: https://www.algorithmiq.fi | J3: https://www.linkedin.com/company/algorithmiq/ | L3: 11-50 | M3: 3 yrs | N3: Finland | O3: Helsinki, Uusimaa | P3: Inglese, Italiano | T3: Title: Assistente all'organizzazione Start At: 2015 Ends At: Present Company: Trieste Mini Maker Faire Cause: Science_and_technology Description: None Title: Assistente all'organizzazione Start At: 2016 Ends At: Present Company: Trieste Mini Maker Faire Cause: Science_and_technology Description: None | U3: Name: IBM Quantum Challenge Authority: IBM Date: 2020-5 URL: https://linkedin.com/company/1009 Name: ECDL Authority: ICDL Europe Date: Unknown URL: https://linkedin.com/company/740915 | V3: Title: Researcher Company: None Start At: None Ends At: None Location: None Description: None Title: Postdoctoral Researcher Company: None Start At: None Ends At: None Location: None Description: None Title: Co-Founder Company: None Start At: None Ends At: None Location: None Description: None Title: PhD Student Company: None Start At: None Ends At: None Location: None Description: None Title: Teaching Assistant Company: None Start At: None Ends At: None Location: None Description: None Title: Teaching assistant Company: None Start At: None Ends At: None Location: None Description: None Title: Quantum Machine Learning Intern Company: None Start At: None Ends At: None Location: None Description: None Title: Mentee Company: None Start At: None Ends At: None Location: None Description: None Title: Internship Company: None Start At: None Ends At: None Location: None Description: None | X3: I am a Research Scientist at Algorithmiq and a PostDoctoral Researcher at the University of Helsinki, and my research focuses on Quantum Computing. Previously, I was a Ph.D. student in Theoretical Physics at the University of Pavia (Italy), where I explored topics in Quantum Computing, and Quantum Machine Learning in particular. Moving on to more serious stuff, I am an optimistic nihilist guy hoping to have a positive impact on the world and the earthlings 🌎. 🤝 Collaborative • 🌱 Vegan • 🗻 Hiker • 🤖 Tech , and many other things. | Y3: Researcher @ Algorithmiq | PostDoc @ University of Helsinki | Z3: Stefano_Mangini.png
A4: Hans Melo | B4: Hans Melo.png | C4: https://www.linkedin.com/in/hansmelo | D4: 3725 | E4: hans@menten.ai | F4: Co-Founder and CEO | G4: Menten AI | H4: Biotechnology Research | I4: http://menten.ai | J4: https://www.linkedin.com/company/menten-ai/ | L4: 2-10 | M4: 7 yrs 9 mos | N4: Sweden | O4: Stockholm, Stockholm County | P4: Chinese, English | Q4: Title: Designing Peptides on a Quantum Computer Source: biorXiv Summary: Here we describe our mapping of the protein design problem to the D-Wave quantum annealer. URL: https://www.biorxiv.org/content/biorxiv/early/2019/09/02/752485.full.pdf Title: Origins of emotional consciousness. Source: Behavioral and Brain Sciences / Volume 39 Summary: None URL: https://www.cambridge.org/core/journals/behavioral-and-brain-sciences/article/div-classtitleorigins-of-emotional-consciousnessdiv/4E8E8BE2FC646BD267725F8E44D26066 Title: Reward: A marketer’s guide to the biological basis of pleasure. In M. Cerf & M. Garcia (Eds). Consumer Neurosciences. Source: MIT Press. Summary: None URL: None Title: Hierarchical Brain Systems Support Multiple Representations of Valence and Mixed Affect. Source: Emotion Review. Summary: None URL: None Title: Imaging Genetics of Positive Psychology. In Genetics of Psychological Well-being. Ed. Michael Pluess. Source: Oxford University Press. Summary: None URL: https://global.oup.com/academic/product/genetics-of-psychological-well-being-9780199686674?cc=us&lang=en& Title: The Function of Positive Emotions in Exploration. Positive Neuroscience. Eds. Greene, Morrison, Seligman. Source: Oxford University Press. Summary: None URL: https://global.oup.com/academic/product/positive-neuroscience-9780199977925?cc=us&lang=en&# Title: Kumaran, D., Melo, H.L. (2013) Transitivity performance, relational hierarchy knowledge and awareness: Results of an instructional framing manipulation. Hippocampus. Source: Unknown Summary: None URL: None Title: Kumaran, D., Melo, H.L.,Duzel,E. (2012) The Amygdala supports Learning and Representation of Social Hierarchies in Humans. Neuron. Source: Unknown Summary: None URL: http://www.ncbi.nlm.nih.gov/pubmed/23141075 | T4: Title: Volunteer Start At: 12/2015 Ends At: Present Company: Hospice Toronto Cause: Social_services Description: None | U4: Name: MILA - Deep Learning Summer School 2017 Authority: Université de Montréal Date: 2017-6 URL: https://linkedin.com/company/166700 Name: Data Science Specialization (Online Coursework - Coursera 2013) Authority: The Johns Hopkins University Date: Unknown URL: https://linkedin.com/company/3528 | V4: Title: Co-Founder and CEO Company: None Start At: None Ends At: None Location: None Description: None Title: Deep Learning Engineer Company: None Start At: None Ends At: None Location: None Description: None Title: Researcher/University Lecturer Company: None Start At: None Ends At: None Location: None Description: None Title: International Purchasing Manager Company: None Start At: None Ends At: None Location: None Description: None Title: Decision Science Researcher Company: None Start At: None Ends At: None Location: None Description: None | W4: School: University of Toronto Degree: Doctor of Philosophy (Ph.D.), Computational Neuroscience (Reinforcement Learning) Activities: None School: UCL Degree: Master of Science (MSc), Cognitive and Decision Science Activities: None School: Louisiana State University Degree: Bachelor's Degree, Physics Activities: None | X4: Menten AI is a drug discovery company focused on designing peptides for conditions with high unmet medical need. We develop computational methods for protein design that leverage machine learning and quantum computing. I am interested in diverse applications of quantum computing and machine learning in health and social good. My expertise is in quantum optimization, reinforcement learning, and computer vision (Deep Learning - CNNs). My research interests at the moment are quantum machine learning, constrained programming, meta-learning, few-shot learning, GAN's in general, and biologically inspired models. I have a technical background in Computational Neuroscience, Machine Learning, and Physics. Aside from my research and entrepreneurial work, I also served as a Scientific Advisor for The Decision Lab. www.hansmelo.com | Y4: Co-Founder and CEO at Menten AI - We’re hiring! | Z4: Hans_Melo.png
A5: Boris Sokolov | B5: Boris Sokolov.png | C5: https://www.linkedin.com/in/boris-sokolov-7301a7205 | D5: 321 | E5: boris@algorithmiq.fi | F5: Lead Researcher, co-founder | G5: Algorithmiq | H5: Research | I5: https://www.algorithmiq.fi | J5: https://www.linkedin.com/company/algorithmiq/ | L5: 11-50 | M5: 5 yrs 4 mos | N5: Finland | O5: Helsinki, Uusimaa | V5: Title: Lead Researcher, co-founder Company: None Start At: None Ends At: None Location: None Description: None | W5: School: Turun yliopisto - University of Turku Degree: Doctor of Philosophy - PhD, Theoretical and Mathematical Physics Activities: None | Y5: Senior Researcher at Algorithmiq Oy | Z5: Boris_Sokolov.png
A6: Sabrina Maniscalco | B6: Sabrina Maniscalco.png | C6: https://www.linkedin.com/in/sabrina-maniscalco | D6: 5501 | E6: sabrina.maniscalco@algorithmiq.fi | F6: Co-founder and CEO | G6: Algorithmiq | H6: Research | I6: https://www.algorithmiq.fi | J6: https://www.linkedin.com/company/algorithmiq/ | L6: 11-50 | M6: 5 yrs 8 mos | N6: Finland | O6: Helsinki, Uusimaa | V6: Title: Co-founder and CEO Company: None Start At: None Ends At: None Location: None Description: None Title: Chief Executive Officer Company: None Start At: None Ends At: None Location: None Description: None Title: Professor of Quantum Information, Computing, and Logic Company: None Start At: None Ends At: None Location: None Description: None Title: Adjunct Professor Company: None Start At: None Ends At: None Location: None Description: None Title: Professor, Chair of Theoretical Physics Company: None Start At: None Ends At: None Location: None Description: None Title: Associate Professor Company: None Start At: None Ends At: None Location: None Description: None | Y6: Co-founder and CEO, Algorithmiq Ltd | Z6: Sabrina_Maniscalco.png
A7: Daniel Cavalcanti | B7: Daniel Cavalcanti.png | C7: https://www.linkedin.com/in/dani-cavalcanti | D7: 1461 | E7: daniel@algorithmiq.fi | F7: Lead Researcher | G7: Algorithmiq | H7: Research | I7: https://www.algorithmiq.fi | J7: https://www.linkedin.com/company/algorithmiq/ | L7: 11-50 | M7: 2 yrs 9 mos | N7: Spain | O7: Barcelona, Catalonia | P7: English, Portuguese | Q7: Title: Publications on quantum physics Source: Unknown Summary: I have published over 100 research articles in peer-reviewed journals such as Nature, Physical Review Letters, and Optica. See my publication list at https://scholar.google.com/citations?user=MeuusYcAAAAJ&hl=en URL: https://arxiv.org/search/quant-ph?searchtype=author&query=Cavalcanti%2C+D Title: Split, But Still attached Source: Science Summary: Invited perspective article written for Science. URL: http://science.sciencemag.org/content/360/6387/376.summary | V7: Title: Lead Researcher Company: None Start At: None Ends At: None Location: None Description: None Title: Senior Researcher | Brand and Communication Director Company: None Start At: None Ends At: None Location: None Description: None Title: Founder and Creative Director Company: None Start At: None Ends At: None Location: None Description: None Title: Associate Professor Company: None Start At: None Ends At: None Location: None Description: None Title: Senior Researcher Company: None Start At: None Ends At: None Location: None Description: None Title: Postdoctoral Fellow Company: None Start At: None Ends At: None Location: None Description: None Title: Postdoctoral Researcher Company: None Start At: None Ends At: None Location: None Description: None | W7: School: Universitat de Barcelona Degree: Doctor of Philosophy - PhD, Physics Activities: None School: Elisava School of Design and Engineering Degree: Summer school, Infography and visualisation of information Activities: None School: IDEP BARCELONA Escuela Superior de Imagen y Diseño (UAO) Degree: Postgraduate course, Graphic Design Activities: None School: IDEP BARCELONA Escuela Superior de Imagen y Diseño (UAO) Degree: Master of Arts - MA, Graphic Design Activities: None School: Universidade Federal de Minas Gerais Degree: Master of Science - MS, Physics Activities: None School: Universidade Federal de Minas Gerais Degree: Bachelor's degree, Physics Activities: None | X7: I am a quantum physicist with over 15 years of post-PhD experience in both academia and industry, and a proven track record of advancing the frontiers of quantum technologies. My research contributions span more than 100 peer-reviewed publications, covering fundamental aspects of quantum information, quantum measurements, and computational methods. Currently, I serve as a Senior Scientist at Algorithmiq, where I lead a research group focused on the development of advanced quantum measurement techniques and their integration with high-performance computing (HPC). My work bridges theory and application, driving innovations that enable scalable quantum software solutions and accelerate the path toward practical quantum advantage. In addition to my scientific career, I am also a trained graphic designer, with a strong belief in the importance of scientific and technological communication. I value clarity, accessibility, and creativity in how complex ideas are shared with diverse audiences. | Y7: Lead Quantum Information Researcher | Z7: Daniel_Cavalcanti.png
A8: Nathalie Wuylens | C8: https://www.linkedin.com/in/nathalie-wuylens-6687b38 | D8: 375 | E8: nathalie.wuylens@qubit-pharmaceuticals.com | F8: Directrice générale déléguée | G8: Qubit Pharmaceuticals | H8: Software Development | I8: https://www.qubit-pharmaceuticals.com | J8: https://www.linkedin.com/company/qubit-pharmaceuticals/ | L8: 51-200 | M8: 2 yrs | N8: France | O8: Paris, Île-de-France | V8: Title: Directrice générale déléguée Company: None Start At: None Ends At: None Location: None Description: None Title: Directrice Juridique / Legal Director Company: None Start At: None Ends At: None Location: None Description: None Title: Director of legal affairs Company: None Start At: None Ends At: None Location: None Description: None Title: IP legal adviser Company: None Start At: None Ends At: None Location: None Description: None Title: Legal Adviser Company: None Start At: None Ends At: None Location: None Description: None Title: Juriste marques Company: None Start At: None Ends At: None Location: None Description: None Title: Responsable section juridique - BPI Company: None Start At: None Ends At: None Location: None Description: None | W8: School: Paris-Pantheon-Assas University Degree: Doctor of Law (JD), Propriété intellectuelle Activities: None | Y8: Directrice Juridique / Legal Director chez Institut Imagine
A9: Jeff Graf | B9: Jeff Graf.png | C9: https://www.linkedin.com/in/jeff-graf-b557684 | D9: 1625 | E9: jeff.graf@sandboxaq.com | F9: Global Head of Business Development @ SandboxAQ | G9: SandboxAQ | H9: Software Development | I9: https://www.sandboxaq.com/ | J9: https://www.linkedin.com/company/sandboxaq/ | L9: 51-200 | M9: 1 yr 7 mos | N9: United States | O9: San Francisco, California | V9: Title: Global Head of Business Development @ SandboxAQ Company: None Start At: None Ends At: None Location: None Description: None Title: Co-Founder Company: None Start At: None Ends At: None Location: None Description: None Title: Independent Consultant Company: None Start At: None Ends At: None Location: None Description: None Title: Investor & Advisor Company: None Start At: None Ends At: None Location: None Description: None Title: Chief Commercial Officer (CCO) Company: None Start At: None Ends At: None Location: None Description: None Title: Chief Business Officer (CBO) Company: None Start At: None Ends At: None Location: None Description: None Title: Senior Director, Business Development Company: None Start At: None Ends At: None Location: None Description: None Title: Director, Business Development Company: None Start At: None Ends At: None Location: None Description: None Title: Sr Engagement Manager Company: None Start At: None Ends At: None Location: None Description: None Title: Engagement Manager Company: None Start At: None Ends At: None Location: None Description: None Title: Post doctoral fellow Company: None Start At: None Ends At: None Location: None Description: None | W9: School: EPFL Degree: Ph.D., Physics Activities: None School: University of California, Berkeley Degree: PhD, Physics Activities: None School: EPFL Degree: Master, Physics Activities: None | X9: People and thought leader with 15 years of experience across go-to-market strategy and business development in deep-tech. With a broad industry experience, a C-suite network, a business foundation, a multicultural background, and a science PhD, I am an engaging and energizing leader and doer who can motivate, coach, and influence others without formal power across boundaries and levels in large and small organizations. I have a track record of leading and closing complex 100m+ deals with value share across pharma, food and agriculture, and planetary health. | Y9: Biotech executive, ex-Mckinsey | Z9: Jeff_Graf.png
A10: Jack Hidary | B10: Jack Hidary.png | C10: https://www.linkedin.com/in/jackhidary | D10: 37202 | E10: jack@sandboxaq.com | F10: Chief Executive Officer | G10: SandboxAQ | H10: Software Development | I10: https://www.sandboxaq.com/ | J10: https://www.linkedin.com/company/sandboxaq/ | L10: 51-200 | M10: 4 yrs 3 mos | N10: United States | O10: Palo Alto, California | P10: Spanish | V10: Title: Chief Executive Officer Company: None Start At: None Ends At: None Location: None Description: None Title: Author Company: None Start At: None Ends At: None Location: None Description: None Title: Board Member Company: None Start At: None Ends At: None Location: None Description: None Title: Founder Company: None Start At: None Ends At: None Location: None Description: None Title: Sandbox Group Director Company: None Start At: None Ends At: None Location: None Description: None Title: Chairman Company: None Start At: None Ends At: None Location: None Description: None Title: Board member Company: None Start At: None Ends At: None Location: None Description: None Title: Member Company: None Start At: None Ends At: None Location: None Description: None Title: GLT - DAVOS Company: None Start At: None Ends At: None Location: None Description: None Title: Chairman and Co-founder Company: None Start At: None Ends At: None Location: None Description: None Title: Co-founder, Chairman and CEO Company: None Start At: None Ends At: None Location: None Description: None | W10: School: Columbia University Degree: Philosophy and Neuroscience Activities: None School: National Institutes of Health Degree: Stanley Fellowship in Clinical Neuroscience, Functional neuroimaging Activities: None | X10: Jack is the CEO of SandboxAQ, an enterprise SaaS company delivering AI and quantum tech (AQ) solutions for large enterprises in banking, biopharma, government, and other sectors. Jack is the author of Quantum Computing: An Applied Approach (Springer, 2nd edition), one of the leading textbooks in the field. Combining both quantum computing theory with hands-on coding, the book is extensively used in university classrooms and corporate up-skilling programs. Jack also co-authored the paper Transitioning Organizations to Post-Quantum Cryptography, published in Nature. Jack has been recognized for his leadership by organizations such as HealthCorps and Young Presidents’ Organization (YPO), and he is a member of the World Economic Forum’s Global Future Council. He frequently speaks at major business and technical conferences hosted by The Economist, Forbes, World Economic Forum, Cog X, MIT, and more. As a serial entrepreneur, Jack has launched and led multiple tech startups, including EarthWeb/Dice, a leading tech marketplace, and Vista Research, a fintech company that he and his team sold to Standard and Poors/McGraw-Hill. Jack has served as a board member, advisor, or trustee for numerous organizations, including BT Global, the XPrize, the National Renewable Energy Lab (NREL), the Partnership for New York City, Trickle Up, and the Council on Foreign Relations. Jack studied neuroscience at Columbia and subsequently received the Stanley Fellowship in Clinical Neuroscience at the National Institutes of Health, where he worked on functional brain imaging and neural networks. Jack's Erdös Number is 3. | Y10: SandboxAQ- AI and Quantum | Z10: Jack_Hidary.png
A11: Mitchell Krane | B11: Mitchell Krane.png | C11: https://www.linkedin.com/in/mitchellkrane | D11: 534 | E11: mitchell.krane@sandboxaq.com | F11: Director, Solution Architects & Customer Success | G11: SandboxAQ | H11: Software Development | I11: https://www.sandboxaq.com/ | J11: https://www.linkedin.com/company/sandboxaq/ | L11: 51-200 | M11: 4 mos | N11: United States | O11: Seattle, Washington | U11: Name: AWS Certified Solutions Architect - Associate Authority: Amazon Web Services (AWS) Date: Unknown URL: https://linkedin.com/company/2382910 Name: Certified Information Systems Security Professional (CISSP) Authority: ISC2 Date: Unknown URL: https://linkedin.com/company/26753 | V11: Title: Director, Solution Architects & Customer Success Company: None Start At: None Ends At: None Location: None Description: None Title: Manager, Solutions Architects Company: None Start At: None Ends At: None Location: None Description: None Title: Senior Solutions Architect Company: None Start At: None Ends At: None Location: None Description: None Title: Sr Specialist Solutions Architect - Security Company: None Start At: None Ends At: None Location: None Description: None Title: Specialist Solutions Architect - Security Company: None Start At: None Ends At: None Location: None Description: None Title: Professional Services Consultant - Security Company: None Start At: None Ends At: None Location: None Description: None Title: Endpoint Security Engineer Company: None Start At: None Ends At: None Location: None Description: None Title: Endpoint Security Administrator Company: None Start At: None Ends At: None Location: None Description: None Title: Tactical Craft Engineer/Gunner Company: None Start At: None Ends At: None Location: None Description: None Title: Cyber Security Analyst Company: None Start At: None Ends At: None Location: None Description: None Title: Service Desk Supervisor Company: None Start At: None Ends At: None Location: None Description: None | W11: School: Arizona State University Degree: Bachelor of Science, Information Technology Activities: None | Y11: Director, Solution Architects & Customer Success | Z11: Mitchell_Krane.png
A12: Reese Brown | B12: Reese Brown.png | C12: https://www.linkedin.com/in/reese-brown-74262246 | D12: 4096 | E12: reese.brown@quantinuum.com | F12: Sr. Director Talent Management | G12: Quantinuum | H12: Computer and Network Security | I12: https://www.quantinuum.com | J12: https://www.linkedin.com/company/quantinuumqc/ | L12: 201-500 | M12: 4 mos | N12: United States | O12: Salt Lake City, Utah | V12: Title: Sr. Director Talent Management Company: None Start At: None Ends At: None Location: None Description: None Title: Director Talent Management Company: None Start At: None Ends At: None Location: None Description: None Title: Sr. Talent Manager Company: None Start At: None Ends At: None Location: None Description: None Title: Human Resources Manager Company: None Start At: None Ends At: None Location: None Description: None Title: Sr. HR Services Manager - Mergers & Acquisitions Company: None Start At: None Ends At: None Location: None Description: None Title: HR Manager- Honeywell Quantum Solutions Company: None Start At: None Ends At: None Location: None Description: None Title: HR Manager Company: None Start At: None Ends At: None Location: None Description: None Title: Sr. Staffing Specialist Company: None Start At: None Ends At: None Location: None Description: None Title: Sr. HR Generalist Company: None Start At: None Ends At: None Location: None Description: None Title: HR Generalist Company: None Start At: None Ends At: None Location: None Description: None Title: Human Resources Intern Company: None Start At: None Ends At: None Location: None Description: None Title: Human Resources Intern Company: None Start At: None Ends At: None Location: None Description: None Title: Business Intern Company: None Start At: None Ends At: None Location: None Description: None Title: Agency Marketing Member Company: None Start At: None Ends At: None Location: None Description: None | W12: School: Utah State University Degree: Master of Business Administration - MBA Activities: None School: Utah State University Degree: Master's degree, Human Resources Management/Personnel Administration, General Activities: None School: Utah State University Degree: Bachelor's degree, Marketing Activities: None | Y12: Sr. Director Talent Management at Quantinuum | Z12: Reese_Brown.png
